<?xml version="1.0"?>

<robot name="fivedof">

  <!-- ******************************************************** -->
  <!-- ******************* Kinematic Chain ******************** -->
  <!-- ******************************************************** -->
  <!-- Note the 'origin' tag in the joints defines the shift and
       reorientation, i.e. the transform.  For moving joints, this
       happens before the continuous joint rotates around 'axis'. -->

  <!-- ALL LENGTHS IN M -->

  <!-- World can't take a visual element (at least in Gazebo). -->
  <link name="world"/>

  <joint name="placement" type="fixed">
    <parent link="world"/>
    <child  link="baseplate"/>
    <origin xyz="0.0 0.0394 0.0" rpy="0 0 0"/>			<!-- WHERE IS THE BASE -->
  </joint>

  <!-- BASE PLATE: Shift across the base plate to the base motor. --> 
  <link name="baseplate">
    <visual>
      <origin xyz="0.0 0.0 0.00625" rpy="0 0 0"/>
      <geometry>
	<box size="0.2 0.1 0.0125"/>
      </geometry>
      <material name="wood"/>
    </visual>
  </link>

  <joint name="baseplate" type="fixed">
    <parent link="baseplate"/>
    <child  link="basemotor"/>
    <origin xyz="0 0 0.0125" rpy="0 0 -1.5708"/>
  </joint>

  <!-- BASE MOTOR: Thickness: X5 = 31.1mm, X8 = 45.1mm -->
  <link name="basemotor">
    <visual>
      <geometry>
        <mesh filename="package://sixdof/meshes/X5.stl"
	      scale="0.001 0.001 0.001"/>
      </geometry>
      <material name="hebi"/>
    </visual>
  </link>

  <joint name="base" type="continuous">
    <parent link="basemotor"/>
    <child  link="lbracket"/>
    <origin xyz="0 0 0.0311" rpy="0 0 0"/>
    <axis   xyz="0 0 1"/>
  </joint>

  <!-- L BRACKET: Shift and rotate across the L bracket. -->
  <link name="lbracket">
    <visual>
      <origin xyz="-0.0475 -0.030 0.0" rpy="0.0 0.0 0.0"/>
      <geometry>
        <mesh filename="package://sixdof/meshes/basebracket.STL"
	      scale="0.001 0.001 0.001"/>
      </geometry>
      <material name="graybracket"/>
    </visual>
  </link>

  <joint name="lbracket" type="fixed">
    <parent link="lbracket"/>
    <child  link="shouldermotor"/>
    <origin xyz="0 0.040 0.085" rpy="1.5708 -1.5708 0.0"/>	  <!-- L BRACKET DIMENIONS -->
  </joint>

  <!-- SHOULDER MOTOR: Thickness: X5 = 31.1mm, X8 = 45.1mm -->
  <link name="shouldermotor">
    <visual>
      <geometry>
        <mesh filename="package://sixdof/meshes/X8.stl"
	      scale="0.001 0.001 0.001"/>
      </geometry>
      <material name="hebi"/>
    </visual>
  </link>

  <joint name="shoulder" type="continuous">
    <parent link="shouldermotor"/>
    <child  link="upperarm"/>
    <origin xyz="0 0 0.0451" rpy="0 0 -1.5708"/>
    <axis   xyz="0 0 1"/>
  </joint>

  <!-- UPPER ARM: Shift across the upper arm -->
  <link name="upperarm">
    <visual>
      <origin xyz="0.05222 -0.040 0.0465" rpy="0.0 3.1415 0.0"/>
      <geometry>
        <mesh filename="package://sixdof/meshes/upperarm.STL"
	      scale="0.001 0.001 0.001"/>
      </geometry>
      <material name="wood"/>
    </visual>
  </link>

  <joint name="upperarm" type="fixed">
    <parent link="upperarm"/>
    <child  link="elbowmotor"/>
    <origin xyz="0.0 0.45 0.0" rpy="0 3.1415 -1.5708"/>
  </joint>

  <!-- Elbow motor.  Thickness: X5 = 31.1mm, X8 = 45.1mm -->
  <link name="elbowmotor">
    <visual>
      <geometry>
        <mesh filename="package://sixdof/meshes/X8.stl"
	      scale="0.001 0.001 0.001"/>
      </geometry>
      <material name="hebi"/>
    </visual>
  </link>

  <joint name="elbow" type="continuous">
    <parent link="elbowmotor"/>
    <child  link="lowerarm"/>
    <origin xyz="0 0 0.0451" rpy="0 0 0.0"/>
    <axis   xyz="0 0 1"/>
  </joint>

  <!-- Shift across the upper arm -->
  <link name="lowerarm">
    <visual>
      <origin xyz="-0.05 -0.050 0.0" rpy="0.0 0.0 0.0"/>
      <geometry>
        <mesh filename="package://sixdof/meshes/lowerarm.STL"
	      scale="0.001 0.001 0.001"/>
      </geometry>
      <material name="wood"/>
    </visual>
  </link>

  <joint name="lowerarm" type="fixed">
    <parent link="lowerarm"/>
    <child  link="wristmotor"/>
    <origin xyz="0.45 0.0 0.0" rpy="3.1415 0 0"/>		  <!-- UPPER ARM DIMENIONS -->
  </joint>

  <!-- Wrist motor: Thickness X5: 31.1mm -->
  <link name="wristmotor">
    <visual>
      <geometry>
        <mesh filename="package://sixdof/meshes/X5.stl"
	      scale="0.001 0.001 0.001"/>
      </geometry>
      <material name="hebi"/>
    </visual>
  </link>

  <joint name="wristpitch" type="continuous">
    <parent link="wristmotor"/>
    <child  link="wristbracket"/>
    <origin xyz="0 0 0.0311" rpy="0.0 0 0.0"/>
    <axis   xyz="0 0 1"/>
  </joint>

  <!-- Wrist BRACKET: Shift and rotate across the L bracket. -->
  <link name="wristbracket">
    <visual>
      <origin xyz="-0.0475 -0.0411 0.181" rpy="0.0 3.1415 -1.5708"/>
      <geometry>
        <mesh filename="package://sixdof/meshes/wristbracket.STL"
	      scale="0.001 0.001 0.001"/>
      </geometry>
      <material name="wristbracket"/>
    </visual>
  </link>

  <joint name="wristbracket" type="fixed">
    <parent link="wristbracket"/>
    <child  link="rollmotor"/>
    <origin xyz="0.0 -0.040 0.06319" rpy="-1.5708 1.5708 0"/>		  
  </joint>

  <link name="rollmotor">
    <visual>
      <geometry>
        <mesh filename="package://sixdof/meshes/X5.stl"
	      scale="0.001 0.001 0.001"/>
      </geometry>
      <material name="hebi"/>
    </visual>
  </link>

  <joint name="wristroll" type="continuous">
    <parent link="rollmotor"/>
    <child  link="gripper"/>
    <origin xyz="0 0 0.0311" rpy="0.0 0 0.0"/>
    <axis   xyz="0 0 1"/>
  </joint>
  
  <link name="gripper">
    <visual>
      <origin xyz="-0.057 0.025 -0.016" rpy="1.5708 0.0 0.0"/>
      <geometry>
        <mesh filename="package://sixdof/meshes/gripper.STL"
	      scale="0.001 0.001 0.001"/>
      </geometry>
      <material name="wood"/>
    </visual>
  </link>

  <joint name="gripper" type="fixed">
    <parent link="gripper"/>
    <child  link="tip"/>
    <origin xyz="0.0 0.0 0.15821" rpy="0.0 0.0 0.0"/>		  
  </joint>

  <link name="tip"/>


  <!-- *************************************************** -->
  <!-- *************** Visual Link Elements ************** -->
  <!-- *************************************************** -->
  <!-- Note collada .dae files have better color/texture   -->
  <!-- suppport that STL files.                            -->

  <!-- Colors -->
  <material name="wood">  <color rgba="0.82 0.62 0.04 1"/>  </material>
  <material name="hebi">  <color rgba="0.82 0.06 0.06 1"/>  </material>
  <material name="graybracket"> <color rgba="0.25 0.25 0.25 1"/> </material>
  <material name="wristbracket">  <color rgba="0.82 0.15 0.15 1"/>  </material>

</robot>